<?xml version="1.0" ?>
<!-- Generated using onshape-to-robot -->
<!-- Onshape document_id: 9c20b098af12cbd02fc50d1f / workspace_id: 91f9e8051518d9fb326b8e23 -->
<mujoco model="catbot">
  <compiler angle="radian" meshdir="meshes" autolimits="true"/>
  <default>
    <default class="catbot">
      <joint frictionloss="0.1" armature="0.005"/>
      <position kp="50" dampratio="1"/>
      <default class="visual">
        <geom type="mesh" contype="0" conaffinity="0" group="2"/>
      </default>
      <default class="collision">
        <geom group="3"/>
      </default>
    </default>
  </default>
  <worldbody>
    <!-- Link chassisasm -->
    <body name="chassisasm" pos="0 0 0" quat="1 0 0 0" childclass="catbot">
      <freejoint name="chassisasm_freejoint"/>
      <inertial pos="0.0264517 -0.131474 -0.0422285" mass="0.277976" fullinertia="0.00407166 0.00224534 0.00584206 -0.00270182 0.000171103 0.000235939"/>
      <!-- Part part_1 -->
      <geom type="mesh" class="visual" pos="0.0860451 -0.0258958 -0.0543461" quat="1 6.76542e-17 1.11022e-16 1.97215e-31" mesh="part_1" material="part_1_material"/>
      <geom type="mesh" class="collision" pos="0.0860451 -0.0258958 -0.0543461" quat="1 6.76542e-17 1.11022e-16 1.97215e-31" mesh="part_1" material="part_1_material"/>
      <!-- Part part_1_2 -->
      <geom type="mesh" class="visual" pos="-0.00145492 -0.00297075 -0.00637113" quat="0.707107 -0.707107 0 0" mesh="part_1__2" material="part_1__2_material"/>
      <geom type="mesh" class="collision" pos="-0.00145492 -0.00297075 -0.00637113" quat="0.707107 -0.707107 0 0" mesh="part_1__2" material="part_1__2_material"/>
      <!-- Part motor_controller_holder -->
      <geom type="mesh" class="visual" pos="-0.0889549 -0.0170208 -0.0118461" quat="1.11022e-16 -0 1 3.33067e-16" mesh="motor_controller_holder" material="motor_controller_holder_material"/>
      <geom type="mesh" class="collision" pos="-0.0889549 -0.0170208 -0.0118461" quat="1.11022e-16 -0 1 3.33067e-16" mesh="motor_controller_holder" material="motor_controller_holder_material"/>
      <!-- Part part_1_3 -->
      <geom type="mesh" class="visual" pos="-0.0889549 0.0199542 -0.0543461" quat="1.27761e-16 -1 -0 4.95635e-17" mesh="part_1" material="part_1_material"/>
      <geom type="mesh" class="collision" pos="-0.0889549 0.0199542 -0.0543461" quat="1.27761e-16 -1 -0 4.95635e-17" mesh="part_1" material="part_1_material"/>
      <!-- Part part_1_4 -->
      <geom type="mesh" class="visual" pos="-0.0889549 -0.0258958 -0.0543461" quat="1 2.77556e-17 0 -4.93038e-32" mesh="part_1" material="part_1_material"/>
      <geom type="mesh" class="collision" pos="-0.0889549 -0.0258958 -0.0543461" quat="1 2.77556e-17 0 -4.93038e-32" mesh="part_1" material="part_1_material"/>
      <!-- Part x2_8010632f54c130b130fc30b903a6_x0_10x9_5l_side_code_g_2 -->
      <geom type="mesh" class="visual" pos="-0.089125 -0.0170208 -0.0543478" quat="0.5 -0.5 0.5 0.5" mesh="x2_8010632f54c130b130fc30b903a6_x0_10x9_5l_side_code_g_2" material="x2_8010632f54c130b130fc30b903a6_x0_10x9_5l_side_code_g_2_material"/>
      <geom type="mesh" class="collision" pos="-0.089125 -0.0170208 -0.0543478" quat="0.5 -0.5 0.5 0.5" mesh="x2_8010632f54c130b130fc30b903a6_x0_10x9_5l_side_code_g_2" material="x2_8010632f54c130b130fc30b903a6_x0_10x9_5l_side_code_g_2_material"/>
      <!-- Part motor_controller_holder_2 -->
      <geom type="mesh" class="visual" pos="-0.0889549 0.0110792 -0.0118461" quat="6.65283e-17 -1 -2.46519e-32 -6.12323e-17" mesh="motor_controller_holder" material="motor_controller_holder_material"/>
      <geom type="mesh" class="collision" pos="-0.0889549 0.0110792 -0.0118461" quat="6.65283e-17 -1 -2.46519e-32 -6.12323e-17" mesh="motor_controller_holder" material="motor_controller_holder_material"/>
      <!-- Part x2_8010632f54c130b130fc30b903a6_x0_10x9_5l_side_code_g_2_2 -->
      <geom type="mesh" class="visual" pos="0.0862152 0.0110792 -0.05435" quat="0.5 0.5 0.5 -0.5" mesh="x2_8010632f54c130b130fc30b903a6_x0_10x9_5l_side_code_g_2" material="x2_8010632f54c130b130fc30b903a6_x0_10x9_5l_side_code_g_2_material"/>
      <geom type="mesh" class="collision" pos="0.0862152 0.0110792 -0.05435" quat="0.5 0.5 0.5 -0.5" mesh="x2_8010632f54c130b130fc30b903a6_x0_10x9_5l_side_code_g_2" material="x2_8010632f54c130b130fc30b903a6_x0_10x9_5l_side_code_g_2_material"/>
      <!-- Part motor_holder -->
      <geom type="mesh" class="visual" pos="-0.0889549 -0.0525708 -0.0388461" quat="6.65283e-17 -1 1.2326e-32 -4.95635e-17" mesh="motor_holder" material="motor_holder_material"/>
      <geom type="mesh" class="collision" pos="-0.0889549 -0.0525708 -0.0388461" quat="6.65283e-17 -1 1.2326e-32 -4.95635e-17" mesh="motor_holder" material="motor_holder_material"/>
      <!-- Part bearing_mount -->
      <geom type="mesh" class="visual" pos="-0.0889549 -0.290423 -0.0543461" quat="1.2326e-32 0 -1 -9.71445e-17" mesh="bearing_mount" material="bearing_mount_material"/>
      <geom type="mesh" class="collision" pos="-0.0889549 -0.290423 -0.0543461" quat="1.2326e-32 0 -1 -9.71445e-17" mesh="bearing_mount" material="bearing_mount_material"/>
      <!-- Part bearing_mount_2 -->
      <geom type="mesh" class="visual" pos="0.0860451 -0.290423 -0.0543461" quat="1.2326e-32 0 -1 -9.71445e-17" mesh="bearing_mount__2" material="bearing_mount__2_material"/>
      <geom type="mesh" class="collision" pos="0.0860451 -0.290423 -0.0543461" quat="1.2326e-32 0 -1 -9.71445e-17" mesh="bearing_mount__2" material="bearing_mount__2_material"/>
      <!-- Part x2_8010632f54c130b130fc30b903a6_x0_10x9_5l_side_code_g_2_3 -->
      <geom type="mesh" class="visual" pos="0.0862152 -0.0170208 -0.0543444" quat="0.5 -0.5 -0.5 -0.5" mesh="x2_8010632f54c130b130fc30b903a6_x0_10x9_5l_side_code_g_2" material="x2_8010632f54c130b130fc30b903a6_x0_10x9_5l_side_code_g_2_material"/>
      <geom type="mesh" class="collision" pos="0.0862152 -0.0170208 -0.0543444" quat="0.5 -0.5 -0.5 -0.5" mesh="x2_8010632f54c130b130fc30b903a6_x0_10x9_5l_side_code_g_2" material="x2_8010632f54c130b130fc30b903a6_x0_10x9_5l_side_code_g_2_material"/>
      <!-- Part motor_controller_holder_3 -->
      <geom type="mesh" class="visual" pos="0.0860451 0.0110792 -0.0118461" quat="6.65283e-17 -1 -2.46519e-32 -6.12323e-17" mesh="motor_controller_holder" material="motor_controller_holder_material"/>
      <geom type="mesh" class="collision" pos="0.0860451 0.0110792 -0.0118461" quat="6.65283e-17 -1 -2.46519e-32 -6.12323e-17" mesh="motor_controller_holder" material="motor_controller_holder_material"/>
      <!-- Part bearing_mount_3 -->
      <geom type="mesh" class="visual" pos="0.0860451 0.284482 -0.0543461" quat="9.71445e-17 -1 -1.11022e-16 1.07852e-32" mesh="bearing_mount__2" material="bearing_mount__2_material"/>
      <geom type="mesh" class="collision" pos="0.0860451 0.284482 -0.0543461" quat="9.71445e-17 -1 -1.11022e-16 1.07852e-32" mesh="bearing_mount__2" material="bearing_mount__2_material"/>
      <!-- Part motor_holder_2 -->
      <geom type="mesh" class="visual" pos="-0.0889549 0.0466292 -0.0388461" quat="1.11022e-16 0 -1 -3.33067e-16" mesh="motor_holder" material="motor_holder_material"/>
      <geom type="mesh" class="collision" pos="-0.0889549 0.0466292 -0.0388461" quat="1.11022e-16 0 -1 -3.33067e-16" mesh="motor_holder" material="motor_holder_material"/>
      <!-- Part motor_controller_holder_4 -->
      <geom type="mesh" class="visual" pos="0.0860451 -0.0170208 -0.0118461" quat="5.55112e-17 0 -1 -2.22045e-16" mesh="motor_controller_holder__2" material="motor_controller_holder__2_material"/>
      <geom type="mesh" class="collision" pos="0.0860451 -0.0170208 -0.0118461" quat="5.55112e-17 0 -1 -2.22045e-16" mesh="motor_controller_holder__2" material="motor_controller_holder__2_material"/>
      <!-- Part part_1_5 -->
      <geom type="mesh" class="visual" pos="0.0860451 0.0199542 -0.0543461" quat="1.27761e-16 -1 -0 4.95635e-17" mesh="part_1" material="part_1_material"/>
      <geom type="mesh" class="collision" pos="0.0860451 0.0199542 -0.0543461" quat="1.27761e-16 -1 -0 4.95635e-17" mesh="part_1" material="part_1_material"/>
      <!-- Part bearing_mount_4 -->
      <geom type="mesh" class="visual" pos="-0.0889549 0.284482 -0.0543461" quat="9.71445e-17 -1 -1.11022e-16 1.07852e-32" mesh="bearing_mount__2" material="bearing_mount__2_material"/>
      <geom type="mesh" class="collision" pos="-0.0889549 0.284482 -0.0543461" quat="9.71445e-17 -1 -1.11022e-16 1.07852e-32" mesh="bearing_mount__2" material="bearing_mount__2_material"/>
      <!-- Part x2_8010632f54c130b130fc30b903a6_x0_10x9_5l_side_code_g_2_4 -->
      <geom type="mesh" class="visual" pos="-0.089125 0.0110792 -0.0543422" quat="0.5 0.5 -0.5 0.5" mesh="x2_8010632f54c130b130fc30b903a6_x0_10x9_5l_side_code_g_2" material="x2_8010632f54c130b130fc30b903a6_x0_10x9_5l_side_code_g_2_material"/>
      <geom type="mesh" class="collision" pos="-0.089125 0.0110792 -0.0543422" quat="0.5 0.5 -0.5 0.5" mesh="x2_8010632f54c130b130fc30b903a6_x0_10x9_5l_side_code_g_2" material="x2_8010632f54c130b130fc30b903a6_x0_10x9_5l_side_code_g_2_material"/>
      <!-- Part motor_holder_3 -->
      <geom type="mesh" class="visual" pos="0.0860451 -0.0525708 -0.0388461" quat="6.65283e-17 -1 1.2326e-32 -4.95635e-17" mesh="motor_holder__2" material="motor_holder__2_material"/>
      <geom type="mesh" class="collision" pos="0.0860451 -0.0525708 -0.0388461" quat="6.65283e-17 -1 1.2326e-32 -4.95635e-17" mesh="motor_holder__2" material="motor_holder__2_material"/>
      <!-- Part motor_holder_4 -->
      <geom type="mesh" class="visual" pos="0.0860451 0.0466292 -0.0388461" quat="1.11022e-16 0 -1 -3.33067e-16" mesh="motor_holder" material="motor_holder_material"/>
      <geom type="mesh" class="collision" pos="0.0860451 0.0466292 -0.0388461" quat="1.11022e-16 0 -1 -3.33067e-16" mesh="motor_holder" material="motor_holder_material"/>
      <!-- Link part_1 -->
      <body name="part_1" pos="-0.0889549 0.0359542 -0.0543461" quat="0.707107 0.707107 -6.66134e-16 5.76981e-16">
        <!-- Joint from chassisasm to part_1 -->
        <joint axis="0 0 1" name="FL_hip" type="hinge"/>
        <inertial pos="0.00392743 0.000156427 -0.173449" mass="0.315" fullinertia="0.000179637 0.000114317 0.000122135 -9.76361e-07 -1.728e-06 9.7673e-07"/>
        <!-- Part part_1_6 -->
        <geom type="mesh" class="visual" pos="0 0 -0.0075" quat="0.5 0.5 0.5 -0.5" mesh="part_1__3" material="part_1__3_material"/>
        <geom type="mesh" class="collision" pos="0 0 -0.0075" quat="0.5 0.5 0.5 -0.5" mesh="part_1__3" material="part_1__3_material"/>
        <!-- Part part_1_7 -->
        <geom type="mesh" class="visual" pos="0 0 0" quat="0.707107 0.707107 -0 -3.52879e-47" mesh="part_1__4" material="part_1__4_material"/>
        <geom type="mesh" class="collision" pos="0 0 0" quat="0.707107 0.707107 -0 -3.52879e-47" mesh="part_1__4" material="part_1__4_material"/>
        <!-- Part hip_joint_to_bearing_shaft -->
        <geom type="mesh" class="visual" pos="-1.11022e-16 4.16334e-17 -0.233675" quat="0.5 0.5 0.5 -0.5" mesh="hip_joint_to_bearing_shaft" material="hip_joint_to_bearing_shaft_material"/>
        <geom type="mesh" class="collision" pos="-1.11022e-16 4.16334e-17 -0.233675" quat="0.5 0.5 0.5 -0.5" mesh="hip_joint_to_bearing_shaft" material="hip_joint_to_bearing_shaft_material"/>
        <!-- Part motor_part_hip_joint -->
        <geom type="mesh" class="visual" pos="-0.017675 4.16334e-17 -0.182425" quat="0.5 0.5 -0.5 0.5" mesh="motor_part_hip_joint" material="motor_part_hip_joint_material"/>
        <geom type="mesh" class="collision" pos="-0.017675 4.16334e-17 -0.182425" quat="0.5 0.5 -0.5 0.5" mesh="motor_part_hip_joint" material="motor_part_hip_joint_material"/>
        <!-- Part x2_8010632f54c130b130fc30b903a6_x0_10x9_5l_side_code_g_2_5 -->
        <geom type="mesh" class="visual" pos="0.017675 -2.80092e-06 -0.173844" quat="0.5 -0.5 0.5 -0.5" mesh="x2_8010632f54c130b130fc30b903a6_x0_10x9_5l_side_code_g_2__2" material="x2_8010632f54c130b130fc30b903a6_x0_10x9_5l_side_code_g_2__2_material"/>
        <geom type="mesh" class="collision" pos="0.017675 -2.80092e-06 -0.173844" quat="0.5 -0.5 0.5 -0.5" mesh="x2_8010632f54c130b130fc30b903a6_x0_10x9_5l_side_code_g_2__2" material="x2_8010632f54c130b130fc30b903a6_x0_10x9_5l_side_code_g_2__2_material"/>
        <!-- Part part_1_8 -->
        <geom type="mesh" class="visual" pos="0.009 6.93889e-17 -0.173675" quat="0.707107 1.30104e-18 2.9877e-16 -0.707107" mesh="part_1__5" material="part_1__5_material"/>
        <geom type="mesh" class="collision" pos="0.009 6.93889e-17 -0.173675" quat="0.707107 1.30104e-18 2.9877e-16 -0.707107" mesh="part_1__5" material="part_1__5_material"/>
        <!-- Part motor_controller_hip_part -->
        <geom type="mesh" class="visual" pos="0.0145 6.245e-17 -0.182425" quat="0.5 0.5 -0.5 0.5" mesh="motor_controller_hip_part" material="motor_controller_hip_part_material"/>
        <geom type="mesh" class="collision" pos="0.0145 6.245e-17 -0.182425" quat="0.5 0.5 -0.5 0.5" mesh="motor_controller_hip_part" material="motor_controller_hip_part_material"/>
        <!-- Part part_1_9 -->
        <geom type="mesh" class="visual" pos="0.009 -2.77556e-17 -0.088675" quat="0.707107 3.33323e-15 2.88658e-15 -0.707107" mesh="part_1" material="part_1_material"/>
        <geom type="mesh" class="collision" pos="0.009 -2.77556e-17 -0.088675" quat="0.707107 3.33323e-15 2.88658e-15 -0.707107" mesh="part_1" material="part_1_material"/>
        <!-- Part spacer -->
        <geom type="mesh" class="visual" pos="-1.11022e-16 3.46945e-17 -0.233675" quat="0.707107 0 -0.707107 0" mesh="spacer" material="spacer_material"/>
        <geom type="mesh" class="collision" pos="-1.11022e-16 3.46945e-17 -0.233675" quat="0.707107 0 -0.707107 0" mesh="spacer" material="spacer_material"/>
        <!-- Part x2_8010632f54c130b130fc30b903a6_x0_10x9_5l_side_code_g_2_6 -->
        <geom type="mesh" class="visual" pos="0.017675 -2.80092e-06 -0.088844" quat="0.5 -0.5 0.5 -0.5" mesh="x2_8010632f54c130b130fc30b903a6_x0_10x9_5l_side_code_g_2" material="x2_8010632f54c130b130fc30b903a6_x0_10x9_5l_side_code_g_2_material"/>
        <geom type="mesh" class="collision" pos="0.017675 -2.80092e-06 -0.088844" quat="0.5 -0.5 0.5 -0.5" mesh="x2_8010632f54c130b130fc30b903a6_x0_10x9_5l_side_code_g_2" material="x2_8010632f54c130b130fc30b903a6_x0_10x9_5l_side_code_g_2_material"/>
        <!-- Part spacer_2 -->
        <geom type="mesh" class="visual" pos="-1.249e-16 0 -0.047725" quat="0.707107 0 -0.707107 -0" mesh="spacer" material="spacer_material"/>
        <geom type="mesh" class="collision" pos="-1.249e-16 0 -0.047725" quat="0.707107 0 -0.707107 -0" mesh="spacer" material="spacer_material"/>
        <!-- Link 68mm -->
        <body name="68mm" pos="-0.007 5.55112e-17 -0.173675" quat="9.28888e-14 -0.707107 9.20375e-14 -0.707107">
          <!-- Joint from part_1 to 68mm -->
          <joint axis="0 0 1" name="FL_l" type="hinge"/>
          <inertial pos="0 0 0" mass="1e-09" fullinertia="1e-09 1e-09 1e-09 0 0 0"/>
          <!-- Part shaftcouplerright -->
          <geom type="mesh" class="visual" pos="0 6.93889e-18 -0.0075" quat="0.5 0.5 -0.5 -0.5" mesh="shaftcouplerright" material="shaftcouplerright_material"/>
          <geom type="mesh" class="collision" pos="0 6.93889e-18 -0.0075" quat="0.5 0.5 -0.5 -0.5" mesh="shaftcouplerright" material="shaftcouplerright_material"/>
          <!-- Part 68mm -->
          <geom type="mesh" class="visual" pos="-0.0200945 0.0145995 -0.0245" quat="0.672499 -0.218508 -0.672499 -0.218508" mesh="68mm" material="68mm_material"/>
          <geom type="mesh" class="collision" pos="-0.0200945 0.0145995 -0.0245" quat="0.672499 -0.218508 -0.672499 -0.218508" mesh="68mm" material="68mm_material"/>
          <!-- Part part_1_10 -->
          <geom type="mesh" class="visual" pos="0 6.93889e-18 0" quat="0.707107 0.707107 0 1.18921e-44" mesh="part_1__4" material="part_1__4_material"/>
          <geom type="mesh" class="collision" pos="0 6.93889e-18 0" quat="0.707107 0.707107 0 1.18921e-44" mesh="part_1__4" material="part_1__4_material"/>
          <!-- Link 225mmbottom -->
          <body name="225mmbottom" pos="-0.0403199 0.0292942 -0.0325" quat="0.891007 9.93997e-15 -1.52101e-14 0.45399">
            <!-- Joint from 68mm to 225mmbottom -->
            <joint axis="0 0 1" name="FL_leg2_2" type="hinge"/>
            <inertial pos="0 0 0" mass="1e-09" fullinertia="1e-09 1e-09 1e-09 0 0 0"/>
            <!-- Part 225mmbottom -->
            <geom type="mesh" class="visual" pos="0.100068 -0.0264312 -0.008" quat="0.091046 -0.701221 0.091046 0.701221" mesh="225mmbottom" material="225mmbottom_material"/>
            <geom type="mesh" class="collision" pos="0.100068 -0.0264312 -0.008" quat="0.091046 -0.701221 0.091046 0.701221" mesh="225mmbottom" material="225mmbottom_material"/>
            <!-- Link 160mm -->
            <body name="160mm" pos="0.200136 -0.0528623 -0.016" quat="0.610175 -1.54252e-14 9.4369e-15 -0.792267">
              <!-- Joint from 225mmbottom to 160mm -->
              <joint axis="0 0 1" name="FL_leg_cyl_1_2" type="hinge"/>
              <inertial pos="0 0 0" mass="1e-09" fullinertia="1e-09 1e-09 1e-09 0 0 0"/>
              <!-- Part 160mm -->
              <geom type="mesh" class="visual" pos="-0.0203083 -0.00534546 -0.008" quat="0.0907459 -0.70126 -0.0907459 -0.70126" mesh="160mm" material="160mm_material"/>
              <geom type="mesh" class="collision" pos="-0.0203083 -0.00534546 -0.008" quat="0.0907459 -0.70126 -0.0907459 -0.70126" mesh="160mm" material="160mm_material"/>
              <!-- Frame closing_FL_leg3_2_1 -->
              <site group="3" name="closing_FL_leg3_2_1" pos="0.048353 0.0127273 1.80411e-15" quat="0.792006 9.23688e-17 8.69561e-17 -0.610514"/>
              <!-- Frame closing_FL_leg3_2_1_z -->
              <site group="3" name="closing_FL_leg3_2_1_z" pos="0.048353 0.0127273 0.1" quat="0.792006 9.23688e-17 8.69561e-17 -0.610514"/>
            </body>
          </body>
          <!-- Link 225mmtop -->
          <body name="225mmtop" pos="-1.66533e-16 -5.01682e-15 -0.0325" quat="0.903178 -5.69483e-17 -1.38778e-16 -0.429266">
            <!-- Joint from 68mm to 225mmtop -->
            <joint axis="0 0 1" name="FL_leg_5_2" type="hinge"/>
            <inertial pos="0 0 0" mass="1e-09" fullinertia="1e-09 1e-09 1e-09 0 0 0"/>
            <!-- Part 225mmtop -->
            <geom type="mesh" class="visual" pos="2.77556e-17 0.1035 -0.008" quat="0.5 -0.5 -0.5 -0.5" mesh="225mmtop" material="225mmtop_material"/>
            <geom type="mesh" class="collision" pos="2.77556e-17 0.1035 -0.008" quat="0.5 -0.5 -0.5 -0.5" mesh="225mmtop" material="225mmtop_material"/>
            <!-- Frame closing_FL_leg3_2_2 -->
            <site group="3" name="closing_FL_leg3_2_2" pos="2.77556e-17 0.207 -0.016" quat="0.707107 0 3.9443e-31 -0.707107"/>
            <!-- Frame closing_FL_leg3_2_2_z -->
            <site group="3" name="closing_FL_leg3_2_2_z" pos="2.77556e-17 0.207 0.084" quat="0.707107 0 3.9443e-31 -0.707107"/>
            <!-- Link 105mm -->
            <body name="105mm" pos="2.77556e-17 0.166278 -0.016" quat="1 0 -3.45127e-31 -2.22045e-16">
              <!-- Joint from 225mmtop to 105mm -->
              <joint axis="0 0 1" name="FL_leg_cyl_0_2" type="hinge"/>
              <inertial pos="0 0 0" mass="1e-09" fullinertia="1e-09 1e-09 1e-09 0 0 0"/>
              <!-- Part 105mm -->
              <geom type="mesh" class="visual" pos="0.0379454 -0.0212695 -0.007" quat="0.178669 0.684162 -0.178669 0.684162" mesh="105mm" material="105mm_material"/>
              <geom type="mesh" class="collision" pos="0.0379454 -0.0212695 -0.007" quat="0.178669 0.684162 -0.178669 0.684162" mesh="105mm" material="105mm_material"/>
              <!-- Frame closing_FL_leg0_2_1 -->
              <site group="3" name="closing_FL_leg0_2_1" pos="0.0758909 -0.0425391 0.001" quat="0.505492 3.46732e-16 -1.11022e-16 -0.862831"/>
              <!-- Frame closing_FL_leg0_2_1_z -->
              <site group="3" name="closing_FL_leg0_2_1_z" pos="0.0758909 -0.0425391 0.101" quat="0.505492 3.46732e-16 -1.11022e-16 -0.862831"/>
            </body>
          </body>
        </body>
        <!-- Link 80mm -->
        <body name="80mm" pos="-0.007 6.93889e-18 -0.088675" quat="2.39793e-14 0.707107 2.43139e-14 0.707107">
          <!-- Joint from part_1 to 80mm -->
          <joint axis="0 0 1" name="FL_a" type="hinge"/>
          <inertial pos="0 0 0" mass="1e-09" fullinertia="1e-09 1e-09 1e-09 0 0 0"/>
          <!-- Part part_1_11 -->
          <geom type="mesh" class="visual" pos="0 0 0" quat="0.707107 0.707107 -0 -3.15306e-32" mesh="part_1__4" material="part_1__4_material"/>
          <geom type="mesh" class="collision" pos="0 0 0" quat="0.707107 0.707107 -0 -3.15306e-32" mesh="part_1__4" material="part_1__4_material"/>
          <!-- Part 80mm -->
          <geom type="mesh" class="visual" pos="0.0293876 0.00971043 -0.0395" quat="0.110616 -0.698401 -0.110616 -0.698401" mesh="80mm" material="80mm_material"/>
          <geom type="mesh" class="collision" pos="0.0293876 0.00971043 -0.0395" quat="0.110616 -0.698401 -0.110616 -0.698401" mesh="80mm" material="80mm_material"/>
          <!-- Part shaftcouplerleft -->
          <geom type="mesh" class="visual" pos="1.38778e-17 0 -0.0075" quat="0.707107 0.707107 -0 -1.33836e-28" mesh="shaftcouplerleft" material="shaftcouplerleft_material"/>
          <geom type="mesh" class="collision" pos="1.38778e-17 0 -0.0075" quat="0.707107 0.707107 -0 -1.33836e-28" mesh="shaftcouplerleft" material="shaftcouplerleft_material"/>
          <!-- Frame closing_FL_leg0_2_2 -->
          <site group="3" name="closing_FL_leg0_2_2" pos="0.0588704 0.01929 -0.0475" quat="0.156434 -5.55112e-17 1.77679e-18 -0.987688"/>
          <!-- Frame closing_FL_leg0_2_2_z -->
          <site group="3" name="closing_FL_leg0_2_2_z" pos="0.0588704 0.01929 0.0525" quat="0.156434 -5.55112e-17 1.77679e-18 -0.987688"/>
        </body>
      </body>
      <!-- Link part_1_2 -->
      <body name="part_1_2" pos="0.0860451 0.0359542 -0.0543461" quat="0.707107 0.707107 1.51879e-13 -1.51829e-13">
        <!-- Joint from chassisasm to part_1_2 -->
        <joint axis="0 0 1" name="FR_hip" type="hinge"/>
        <inertial pos="-0.00392743 -0.000156427 -0.173449" mass="0.315" fullinertia="0.000179637 0.000114317 0.000122135 -9.76361e-07 1.728e-06 -9.7673e-07"/>
        <!-- Part part_1_12 -->
        <geom type="mesh" class="visual" pos="0 -6.93889e-18 -0.028675" quat="0.5 -0.5 -0.5 -0.5" mesh="part_1__3" material="part_1__3_material"/>
        <geom type="mesh" class="collision" pos="0 -6.93889e-18 -0.028675" quat="0.5 -0.5 -0.5 -0.5" mesh="part_1__3" material="part_1__3_material"/>
        <!-- Part hip_joint_to_bearing_shaft_2 -->
        <geom type="mesh" class="visual" pos="0 -4.85723e-17 -0.233675" quat="0.5 0.5 0.5 -0.5" mesh="hip_joint_to_bearing_shaft" material="hip_joint_to_bearing_shaft_material"/>
        <geom type="mesh" class="collision" pos="0 -4.85723e-17 -0.233675" quat="0.5 0.5 0.5 -0.5" mesh="hip_joint_to_bearing_shaft" material="hip_joint_to_bearing_shaft_material"/>
        <!-- Part part_1_13 -->
        <geom type="mesh" class="visual" pos="0 0 0" quat="0.707107 0.707107 -0 1.56929e-45" mesh="part_1__4" material="part_1__4_material"/>
        <geom type="mesh" class="collision" pos="0 0 0" quat="0.707107 0.707107 -0 1.56929e-45" mesh="part_1__4" material="part_1__4_material"/>
        <!-- Part motor_part_hip_joint_2 -->
        <geom type="mesh" class="visual" pos="0.017675 -5.55112e-17 -0.182425" quat="0.5 -0.5 -0.5 -0.5" mesh="motor_part_hip_joint" material="motor_part_hip_joint_material"/>
        <geom type="mesh" class="collision" pos="0.017675 -5.55112e-17 -0.182425" quat="0.5 -0.5 -0.5 -0.5" mesh="motor_part_hip_joint" material="motor_part_hip_joint_material"/>
        <!-- Part x2_8010632f54c130b130fc30b903a6_x0_10x9_5l_side_code_g_2_7 -->
        <geom type="mesh" class="visual" pos="-0.017675 2.80092e-06 -0.173844" quat="0.5 -0.5 -0.5 0.5" mesh="x2_8010632f54c130b130fc30b903a6_x0_10x9_5l_side_code_g_2__2" material="x2_8010632f54c130b130fc30b903a6_x0_10x9_5l_side_code_g_2__2_material"/>
        <geom type="mesh" class="collision" pos="-0.017675 2.80092e-06 -0.173844" quat="0.5 -0.5 -0.5 0.5" mesh="x2_8010632f54c130b130fc30b903a6_x0_10x9_5l_side_code_g_2__2" material="x2_8010632f54c130b130fc30b903a6_x0_10x9_5l_side_code_g_2__2_material"/>
        <!-- Part part_1_14 -->
        <geom type="mesh" class="visual" pos="-0.009 -6.245e-17 -0.173675" quat="0.707107 -0 1.11022e-16 0.707107" mesh="part_1__5" material="part_1__5_material"/>
        <geom type="mesh" class="collision" pos="-0.009 -6.245e-17 -0.173675" quat="0.707107 -0 1.11022e-16 0.707107" mesh="part_1__5" material="part_1__5_material"/>
        <!-- Part motor_controller_hip_part_2 -->
        <geom type="mesh" class="visual" pos="-0.0145 -6.245e-17 -0.182425" quat="0.5 -0.5 -0.5 -0.5" mesh="motor_controller_hip_part" material="motor_controller_hip_part_material"/>
        <geom type="mesh" class="collision" pos="-0.0145 -6.245e-17 -0.182425" quat="0.5 -0.5 -0.5 -0.5" mesh="motor_controller_hip_part" material="motor_controller_hip_part_material"/>
        <!-- Part part_1_15 -->
        <geom type="mesh" class="visual" pos="-0.009 -4.85723e-17 -0.088675" quat="0.707107 -1.35525e-20 1.35672e-16 0.707107" mesh="part_1" material="part_1_material"/>
        <geom type="mesh" class="collision" pos="-0.009 -4.85723e-17 -0.088675" quat="0.707107 -1.35525e-20 1.35672e-16 0.707107" mesh="part_1" material="part_1_material"/>
        <!-- Part spacer_3 -->
        <geom type="mesh" class="visual" pos="0 -4.16334e-17 -0.233675" quat="7.11902e-26 -0.707107 0 -0.707107" mesh="spacer" material="spacer_material"/>
        <geom type="mesh" class="collision" pos="0 -4.16334e-17 -0.233675" quat="7.11902e-26 -0.707107 0 -0.707107" mesh="spacer" material="spacer_material"/>
        <!-- Part x2_8010632f54c130b130fc30b903a6_x0_10x9_5l_side_code_g_2_8 -->
        <geom type="mesh" class="visual" pos="-0.017675 2.80092e-06 -0.088844" quat="0.5 -0.5 -0.5 0.5" mesh="x2_8010632f54c130b130fc30b903a6_x0_10x9_5l_side_code_g_2" material="x2_8010632f54c130b130fc30b903a6_x0_10x9_5l_side_code_g_2_material"/>
        <geom type="mesh" class="collision" pos="-0.017675 2.80092e-06 -0.088844" quat="0.5 -0.5 -0.5 0.5" mesh="x2_8010632f54c130b130fc30b903a6_x0_10x9_5l_side_code_g_2" material="x2_8010632f54c130b130fc30b903a6_x0_10x9_5l_side_code_g_2_material"/>
        <!-- Part spacer_4 -->
        <geom type="mesh" class="visual" pos="0 -6.93889e-18 -0.047725" quat="6.11046e-26 -0.707107 0 -0.707107" mesh="spacer" material="spacer_material"/>
        <geom type="mesh" class="collision" pos="0 -6.93889e-18 -0.047725" quat="6.11046e-26 -0.707107 0 -0.707107" mesh="spacer" material="spacer_material"/>
        <!-- Link 80mm_2 -->
        <body name="80mm_2" pos="0.007 -4.16334e-17 -0.088675" quat="0.5 -0.5 -0.5 0.5">
          <!-- Joint from part_1_2 to 80mm_2 -->
          <joint axis="0 0 1" name="FR_a" type="hinge"/>
          <inertial pos="0 0 0" mass="1e-09" fullinertia="1e-09 1e-09 1e-09 0 0 0"/>
          <!-- Part 80mm_2 -->
          <geom type="mesh" class="visual" pos="-0.00952953 -0.0293289 -0.0395" quat="0.415627 0.572061 0.415627 -0.572061" mesh="80mm" material="80mm_material"/>
          <geom type="mesh" class="collision" pos="-0.00952953 -0.0293289 -0.0395" quat="0.415627 0.572061 0.415627 -0.572061" mesh="80mm" material="80mm_material"/>
          <!-- Part part_1_16 -->
          <geom type="mesh" class="visual" pos="0 0 0" quat="0.707107 0.707107 0 -1.64066e-29" mesh="part_1__4" material="part_1__4_material"/>
          <geom type="mesh" class="collision" pos="0 0 0" quat="0.707107 0.707107 0 -1.64066e-29" mesh="part_1__4" material="part_1__4_material"/>
          <!-- Part shaftcouplerleft_2 -->
          <geom type="mesh" class="visual" pos="6.93889e-18 -1.38778e-17 -0.0075" quat="0.5 0.5 0.5 0.5" mesh="shaftcouplerleft" material="shaftcouplerleft_material"/>
          <geom type="mesh" class="collision" pos="6.93889e-18 -1.38778e-17 -0.0075" quat="0.5 0.5 0.5 0.5" mesh="shaftcouplerleft" material="shaftcouplerleft_material"/>
          <!-- Frame closing_FR_leg0_1_2 -->
          <site group="3" name="closing_FR_leg0_1_2" pos="-0.0191091 -0.0588116 -0.0315" quat="1.49212e-15 -0.809017 -0.587785 -9.42088e-15"/>
          <!-- Frame closing_FR_leg0_1_2_z -->
          <site group="3" name="closing_FR_leg0_1_2_z" pos="-0.0191091 -0.0588116 -0.1315" quat="1.49212e-15 -0.809017 -0.587785 -9.42088e-15"/>
        </body>
        <!-- Link 68mm_2 -->
        <body name="68mm_2" pos="0.007 -5.55112e-17 -0.173675" quat="0.5 -0.5 -0.5 0.5">
          <!-- Joint from part_1_2 to 68mm_2 -->
          <joint axis="0 0 1" name="FR_l" type="hinge"/>
          <inertial pos="0 0 0" mass="1e-09" fullinertia="1e-09 1e-09 1e-09 0 0 0"/>
          <!-- Part shaftcouplerright_2 -->
          <geom type="mesh" class="visual" pos="1.38778e-17 0 -0.0075" quat="1.18738e-14 1.65978e-14 0.707107 0.707107" mesh="shaftcouplerright" material="shaftcouplerright_material"/>
          <geom type="mesh" class="collision" pos="1.38778e-17 0 -0.0075" quat="1.18738e-14 1.65978e-14 0.707107 0.707107" mesh="shaftcouplerright" material="shaftcouplerright_material"/>
          <!-- Part 68mm_2 -->
          <geom type="mesh" class="visual" pos="-0.0145995 0.0200945 -0.0245" quat="0.32102 -0.630037 0.32102 0.630037" mesh="68mm" material="68mm_material"/>
          <geom type="mesh" class="collision" pos="-0.0145995 0.0200945 -0.0245" quat="0.32102 -0.630037 0.32102 0.630037" mesh="68mm" material="68mm_material"/>
          <!-- Part part_1_17 -->
          <geom type="mesh" class="visual" pos="1.38778e-17 0 0" quat="0.5 0.5 -0.5 -0.5" mesh="part_1__4" material="part_1__4_material"/>
          <geom type="mesh" class="collision" pos="1.38778e-17 0 0" quat="0.5 0.5 -0.5 -0.5" mesh="part_1__4" material="part_1__4_material"/>
          <!-- Link 225mmtop_2 -->
          <body name="225mmtop_2" pos="5.23886e-15 2.22045e-16 -0.0325" quat="0.942375 0 -2.22045e-16 -0.334559">
            <!-- Joint from 68mm_2 to 225mmtop_2 -->
            <joint axis="0 0 1" name="FR_leg1_1" type="hinge"/>
            <inertial pos="0 0 0" mass="1e-09" fullinertia="1e-09 1e-09 1e-09 0 0 0"/>
            <!-- Part 225mmtop_2 -->
            <geom type="mesh" class="visual" pos="0 -0.1035 -0.008" quat="0.5 0.5 0.5 -0.5" mesh="225mmtop" material="225mmtop_material"/>
            <geom type="mesh" class="collision" pos="0 -0.1035 -0.008" quat="0.5 0.5 0.5 -0.5" mesh="225mmtop" material="225mmtop_material"/>
            <!-- Frame closing_FR_leg3_1_2 -->
            <site group="3" name="closing_FR_leg3_1_2" pos="2.77556e-17 -0.207 0" quat="2.68745e-31 -0.707107 -0.707107 -2.55624e-29"/>
            <!-- Frame closing_FR_leg3_1_2_z -->
            <site group="3" name="closing_FR_leg3_1_2_z" pos="2.77556e-17 -0.207 -0.1" quat="2.68745e-31 -0.707107 -0.707107 -2.55624e-29"/>
            <!-- Link 105mm_2 -->
            <body name="105mm_2" pos="0 -0.166278 0" quat="0 1 0 0">
              <!-- Joint from 225mmtop_2 to 105mm_2 -->
              <joint axis="0 0 1" name="FR_leg_cyl_0_1" type="hinge"/>
              <inertial pos="0 0 0" mass="1e-09" fullinertia="1e-09 1e-09 1e-09 0 0 0"/>
              <!-- Part 105mm_2 -->
              <geom type="mesh" class="visual" pos="0.0379253 -0.0213054 -0.009" quat="0.178993 0.684077 -0.178993 0.684077" mesh="105mm" material="105mm_material"/>
              <geom type="mesh" class="collision" pos="0.0379253 -0.0213054 -0.009" quat="0.178993 0.684077 -0.178993 0.684077" mesh="105mm" material="105mm_material"/>
              <!-- Frame closing_FR_leg0_1_1 -->
              <site group="3" name="closing_FR_leg0_1_1" pos="0.0758506 -0.0426108 -0.001" quat="0.505085 2.49136e-16 -1.11022e-16 -0.86307"/>
              <!-- Frame closing_FR_leg0_1_1_z -->
              <site group="3" name="closing_FR_leg0_1_1_z" pos="0.0758506 -0.0426108 0.099" quat="0.505085 2.49136e-16 -1.11022e-16 -0.86307"/>
            </body>
          </body>
          <!-- Link 225mmbottom_2 -->
          <body name="225mmbottom_2" pos="-0.0292942 0.0403199 -0.0325" quat="0.942239 -0 -4.85723e-17 -0.33494">
            <!-- Joint from 68mm_2 to 225mmbottom_2 -->
            <joint axis="0 0 1" name="FR_leg2_1" type="hinge"/>
            <inertial pos="0 0 0" mass="1e-09" fullinertia="1e-09 1e-09 1e-09 0 0 0"/>
            <!-- Part 225mmbottom_2 -->
            <geom type="mesh" class="visual" pos="2.77556e-17 -0.1035 -0.008" quat="0.5 -0.5 -0.5 -0.5" mesh="225mmbottom" material="225mmbottom_material"/>
            <geom type="mesh" class="collision" pos="2.77556e-17 -0.1035 -0.008" quat="0.5 -0.5 -0.5 -0.5" mesh="225mmbottom" material="225mmbottom_material"/>
            <!-- Link 160mm_2 -->
            <body name="160mm_2" pos="2.77556e-17 -0.207 0" quat="0 1 0 0">
              <!-- Joint from 225mmbottom_2 to 160mm_2 -->
              <joint axis="0 0 1" name="FR_leg_cyl_1_1" type="hinge"/>
              <inertial pos="0 0 0" mass="1e-09" fullinertia="1e-09 1e-09 1e-09 0 0 0"/>
              <!-- Part 160mm_2 -->
              <geom type="mesh" class="visual" pos="-0.0203021 -0.00536893 -0.008" quat="0.0911511 -0.701207 -0.0911511 -0.701207" mesh="160mm" material="160mm_material"/>
              <geom type="mesh" class="collision" pos="-0.0203021 -0.00536893 -0.008" quat="0.0911511 -0.701207 -0.0911511 -0.701207" mesh="160mm" material="160mm_material"/>
              <!-- Frame closing_FR_leg3_1_1 -->
              <site group="3" name="closing_FR_leg3_1_1" pos="0.0483383 0.0127832 3.05311e-15" quat="0.792358 -0 -7.18161e-18 -0.610056"/>
              <!-- Frame closing_FR_leg3_1_1_z -->
              <site group="3" name="closing_FR_leg3_1_1_z" pos="0.0483383 0.0127832 0.1" quat="0.792358 -0 -7.18161e-18 -0.610056"/>
            </body>
          </body>
        </body>
      </body>
      <!-- Link part_1_3 -->
      <body name="part_1_3" pos="-0.0889549 -0.0418958 -0.0543461" quat="0.707107 -0.707107 -3.33067e-16 2.58153e-16">
        <!-- Joint from chassisasm to part_1_3 -->
        <joint axis="0 0 1" name="BL_hip" type="hinge"/>
        <inertial pos="0.00392743 -0.000156427 -0.0889009" mass="0.315" fullinertia="0.000179637 0.000114317 0.000122135 9.76361e-07 1.728e-06 9.7673e-07"/>
        <!-- Part part_1_18 -->
        <geom type="mesh" class="visual" pos="0 0 0" quat="0.707107 0.707107 -0 4.98962e-33" mesh="part_1__4" material="part_1__4_material"/>
        <geom type="mesh" class="collision" pos="0 0 0" quat="0.707107 0.707107 -0 4.98962e-33" mesh="part_1__4" material="part_1__4_material"/>
        <!-- Part hip_joint_to_bearing_shaft_3 -->
        <geom type="mesh" class="visual" pos="7.77156e-16 -1.94289e-16 -0.233675" quat="0.5 0.5 0.5 -0.5" mesh="hip_joint_to_bearing_shaft" material="hip_joint_to_bearing_shaft_material"/>
        <geom type="mesh" class="collision" pos="7.77156e-16 -1.94289e-16 -0.233675" quat="0.5 0.5 0.5 -0.5" mesh="hip_joint_to_bearing_shaft" material="hip_joint_to_bearing_shaft_material"/>
        <!-- Part part_1_19 -->
        <geom type="mesh" class="visual" pos="0 -6.93889e-18 -0.028675" quat="0.5 -0.5 -0.5 -0.5" mesh="part_1__3" material="part_1__3_material"/>
        <geom type="mesh" class="collision" pos="0 -6.93889e-18 -0.028675" quat="0.5 -0.5 -0.5 -0.5" mesh="part_1__3" material="part_1__3_material"/>
        <!-- Part motor_part_hip_joint_3 -->
        <geom type="mesh" class="visual" pos="-0.017675 -9.71445e-17 -0.079925" quat="0.5 -0.5 0.5 0.5" mesh="motor_part_hip_joint" material="motor_part_hip_joint_material"/>
        <geom type="mesh" class="collision" pos="-0.017675 -9.71445e-17 -0.079925" quat="0.5 -0.5 0.5 0.5" mesh="motor_part_hip_joint" material="motor_part_hip_joint_material"/>
        <!-- Part x2_8010632f54c130b130fc30b903a6_x0_10x9_5l_side_code_g_2_9 -->
        <geom type="mesh" class="visual" pos="0.017675 2.80092e-06 -0.088506" quat="0.5 0.5 0.5 0.5" mesh="x2_8010632f54c130b130fc30b903a6_x0_10x9_5l_side_code_g_2__2" material="x2_8010632f54c130b130fc30b903a6_x0_10x9_5l_side_code_g_2__2_material"/>
        <geom type="mesh" class="collision" pos="0.017675 2.80092e-06 -0.088506" quat="0.5 0.5 0.5 0.5" mesh="x2_8010632f54c130b130fc30b903a6_x0_10x9_5l_side_code_g_2__2" material="x2_8010632f54c130b130fc30b903a6_x0_10x9_5l_side_code_g_2__2_material"/>
        <!-- Part part_1_20 -->
        <geom type="mesh" class="visual" pos="0.009 -1.66533e-16 -0.088675" quat="6.64813e-28 0.707107 0.707107 3.53271e-16" mesh="part_1__5" material="part_1__5_material"/>
        <geom type="mesh" class="collision" pos="0.009 -1.66533e-16 -0.088675" quat="6.64813e-28 0.707107 0.707107 3.53271e-16" mesh="part_1__5" material="part_1__5_material"/>
        <!-- Part motor_controller_hip_part_3 -->
        <geom type="mesh" class="visual" pos="0.0145 -2.498e-16 -0.079925" quat="0.5 -0.5 0.5 0.5" mesh="motor_controller_hip_part" material="motor_controller_hip_part_material"/>
        <geom type="mesh" class="collision" pos="0.0145 -2.498e-16 -0.079925" quat="0.5 -0.5 0.5 0.5" mesh="motor_controller_hip_part" material="motor_controller_hip_part_material"/>
        <!-- Part part_1_21 -->
        <geom type="mesh" class="visual" pos="0.009 -1.66533e-16 -0.173675" quat="3.97863e-28 -0.707107 -0.707107 -1.21481e-27" mesh="part_1" material="part_1_material"/>
        <geom type="mesh" class="collision" pos="0.009 -1.66533e-16 -0.173675" quat="3.97863e-28 -0.707107 -0.707107 -1.21481e-27" mesh="part_1" material="part_1_material"/>
        <!-- Part spacer_5 -->
        <geom type="mesh" class="visual" pos="0 0 -0.028675" quat="9.0771e-17 0.707107 3.33067e-16 -0.707107" mesh="spacer" material="spacer_material"/>
        <geom type="mesh" class="collision" pos="0 0 -0.028675" quat="9.0771e-17 0.707107 3.33067e-16 -0.707107" mesh="spacer" material="spacer_material"/>
        <!-- Part x2_8010632f54c130b130fc30b903a6_x0_10x9_5l_side_code_g_2_10 -->
        <geom type="mesh" class="visual" pos="0.017675 2.80092e-06 -0.173506" quat="0.5 0.5 0.5 0.5" mesh="x2_8010632f54c130b130fc30b903a6_x0_10x9_5l_side_code_g_2" material="x2_8010632f54c130b130fc30b903a6_x0_10x9_5l_side_code_g_2_material"/>
        <geom type="mesh" class="collision" pos="0.017675 2.80092e-06 -0.173506" quat="0.5 0.5 0.5 0.5" mesh="x2_8010632f54c130b130fc30b903a6_x0_10x9_5l_side_code_g_2" material="x2_8010632f54c130b130fc30b903a6_x0_10x9_5l_side_code_g_2_material"/>
        <!-- Part spacer_6 -->
        <geom type="mesh" class="visual" pos="8.04912e-16 -1.80411e-16 -0.214625" quat="8.74904e-17 0.707107 0 -0.707107" mesh="spacer" material="spacer_material"/>
        <geom type="mesh" class="collision" pos="8.04912e-16 -1.80411e-16 -0.214625" quat="8.74904e-17 0.707107 0 -0.707107" mesh="spacer" material="spacer_material"/>
        <!-- Link 80mm_3 -->
        <body name="80mm_3" pos="-0.007 -1.66533e-16 -0.173675" quat="0.707107 5.6629e-14 0.707107 5.67602e-14">
          <!-- Joint from part_1_3 to 80mm_3 -->
          <joint axis="0 0 1" name="BL_a" type="hinge"/>
          <inertial pos="0 0 0" mass="1e-09" fullinertia="1e-09 1e-09 1e-09 0 0 0"/>
          <!-- Part part_1_22 -->
          <geom type="mesh" class="visual" pos="0 0 0" quat="0.707107 0.707107 0 -3.99199e-30" mesh="part_1__4" material="part_1__4_material"/>
          <geom type="mesh" class="collision" pos="0 0 0" quat="0.707107 0.707107 0 -3.99199e-30" mesh="part_1__4" material="part_1__4_material"/>
          <!-- Part 80mm_3 -->
          <geom type="mesh" class="visual" pos="0.0293876 0.00971043 -0.0395" quat="0.110616 -0.698401 -0.110616 -0.698401" mesh="80mm" material="80mm_material"/>
          <geom type="mesh" class="collision" pos="0.0293876 0.00971043 -0.0395" quat="0.110616 -0.698401 -0.110616 -0.698401" mesh="80mm" material="80mm_material"/>
          <!-- Part shaftcouplerleft_3 -->
          <geom type="mesh" class="visual" pos="-2.77556e-17 0 -0.0075" quat="0.707107 0.707107 -3.33067e-16 2.09851e-16" mesh="shaftcouplerleft" material="shaftcouplerleft_material"/>
          <geom type="mesh" class="collision" pos="-2.77556e-17 0 -0.0075" quat="0.707107 0.707107 -3.33067e-16 2.09851e-16" mesh="shaftcouplerleft" material="shaftcouplerleft_material"/>
          <!-- Frame closing_BL_leg0_2_1_2 -->
          <site group="3" name="closing_BL_leg0_2_1_2" pos="0.0588704 0.01929 -0.0475" quat="0.156434 4.04033e-16 -2.22045e-16 -0.987688"/>
          <!-- Frame closing_BL_leg0_2_1_2_z -->
          <site group="3" name="closing_BL_leg0_2_1_2_z" pos="0.0588704 0.01929 0.0525" quat="0.156434 4.04033e-16 -2.22045e-16 -0.987688"/>
        </body>
        <!-- Link 68mm_3 -->
        <body name="68mm_3" pos="-0.007 -1.249e-16 -0.088675" quat="0.707107 2.51769e-14 0.707107 2.38239e-14">
          <!-- Joint from part_1_3 to 68mm_3 -->
          <joint axis="0 0 1" name="BL_l" type="hinge"/>
          <inertial pos="0 0 0" mass="1e-09" fullinertia="1e-09 1e-09 1e-09 0 0 0"/>
          <!-- Part part_1_23 -->
          <geom type="mesh" class="visual" pos="0 0 0" quat="0.707107 0.707107 -0 -1.72287e-32" mesh="part_1__4" material="part_1__4_material"/>
          <geom type="mesh" class="collision" pos="0 0 0" quat="0.707107 0.707107 -0 -1.72287e-32" mesh="part_1__4" material="part_1__4_material"/>
          <!-- Part shaftcouplerright_3 -->
          <geom type="mesh" class="visual" pos="0 -6.93889e-18 -0.0075" quat="0.5 0.5 -0.5 -0.5" mesh="shaftcouplerright" material="shaftcouplerright_material"/>
          <geom type="mesh" class="collision" pos="0 -6.93889e-18 -0.0075" quat="0.5 0.5 -0.5 -0.5" mesh="shaftcouplerright" material="shaftcouplerright_material"/>
          <!-- Part 68mm_3 -->
          <geom type="mesh" class="visual" pos="-0.0200945 0.0145995 -0.0245" quat="0.672499 -0.218508 -0.672499 -0.218508" mesh="68mm" material="68mm_material"/>
          <geom type="mesh" class="collision" pos="-0.0200945 0.0145995 -0.0245" quat="0.672499 -0.218508 -0.672499 -0.218508" mesh="68mm" material="68mm_material"/>
          <!-- Link 225mmbottom_3 -->
          <body name="225mmbottom_3" pos="-0.0403199 0.0292942 -0.0325" quat="0.891007 6.55e-16 -2.22045e-15 0.45399">
            <!-- Joint from 68mm_3 to 225mmbottom_3 -->
            <joint axis="0 0 1" name="BL_leg2_2_1" type="hinge"/>
            <inertial pos="0 0 0" mass="1e-09" fullinertia="1e-09 1e-09 1e-09 0 0 0"/>
            <!-- Part 225mmbottom_3 -->
            <geom type="mesh" class="visual" pos="0.100068 -0.0264312 -0.008" quat="0.091046 -0.701221 0.091046 0.701221" mesh="225mmbottom" material="225mmbottom_material"/>
            <geom type="mesh" class="collision" pos="0.100068 -0.0264312 -0.008" quat="0.091046 -0.701221 0.091046 0.701221" mesh="225mmbottom" material="225mmbottom_material"/>
            <!-- Link 160mm_3 -->
            <body name="160mm_3" pos="0.200136 -0.0528623 -0.016" quat="0.610175 -2.21992e-15 2.10942e-15 -0.792267">
              <!-- Joint from 225mmbottom_3 to 160mm_3 -->
              <joint axis="0 0 1" name="BL_leg_cyl_1_2_1" type="hinge"/>
              <inertial pos="0 0 0" mass="1e-09" fullinertia="1e-09 1e-09 1e-09 0 0 0"/>
              <!-- Part 160mm_3 -->
              <geom type="mesh" class="visual" pos="-0.0203083 -0.00534546 -0.008" quat="0.0907459 -0.70126 -0.0907459 -0.70126" mesh="160mm" material="160mm_material"/>
              <geom type="mesh" class="collision" pos="-0.0203083 -0.00534546 -0.008" quat="0.0907459 -0.70126 -0.0907459 -0.70126" mesh="160mm" material="160mm_material"/>
              <!-- Frame closing_BL_leg3_2_1_1 -->
              <site group="3" name="closing_BL_leg3_2_1_1" pos="0.048353 0.0127273 -1.11022e-16" quat="0.792006 -3.21781e-17 -1.64441e-16 -0.610514"/>
              <!-- Frame closing_BL_leg3_2_1_1_z -->
              <site group="3" name="closing_BL_leg3_2_1_1_z" pos="0.048353 0.0127273 0.1" quat="0.792006 -3.21781e-17 -1.64441e-16 -0.610514"/>
            </body>
          </body>
          <!-- Link 225mmtop_3 -->
          <body name="225mmtop_3" pos="-2.77556e-17 -1.38778e-17 -0.0325" quat="0.903178 -9.98535e-16 3.33067e-16 -0.429266">
            <!-- Joint from 68mm_3 to 225mmtop_3 -->
            <joint axis="0 0 1" name="BL_leg_5_2_1" type="hinge"/>
            <inertial pos="0 0 0" mass="1e-09" fullinertia="1e-09 1e-09 1e-09 0 0 0"/>
            <!-- Part 225mmtop_3 -->
            <geom type="mesh" class="visual" pos="6.93889e-18 0.1035 -0.008" quat="0.5 -0.5 -0.5 -0.5" mesh="225mmtop" material="225mmtop_material"/>
            <geom type="mesh" class="collision" pos="6.93889e-18 0.1035 -0.008" quat="0.5 -0.5 -0.5 -0.5" mesh="225mmtop" material="225mmtop_material"/>
            <!-- Frame closing_BL_leg3_2_1_2 -->
            <site group="3" name="closing_BL_leg3_2_1_2" pos="2.08167e-17 0.207 -0.016" quat="0.707107 0 2.22045e-16 -0.707107"/>
            <!-- Frame closing_BL_leg3_2_1_2_z -->
            <site group="3" name="closing_BL_leg3_2_1_2_z" pos="3.46945e-17 0.207 0.084" quat="0.707107 0 2.22045e-16 -0.707107"/>
            <!-- Link 105mm_3 -->
            <body name="105mm_3" pos="-6.93889e-18 0.166278 -0.016" quat="1 6.93889e-18 -8.40521e-18 -4.30029e-32">
              <!-- Joint from 225mmtop_3 to 105mm_3 -->
              <joint axis="0 0 1" name="BL_leg_cyl_0_2_1" type="hinge"/>
              <inertial pos="0 0 0" mass="1e-09" fullinertia="1e-09 1e-09 1e-09 0 0 0"/>
              <!-- Part 105mm_3 -->
              <geom type="mesh" class="visual" pos="0.0379454 -0.0212695 -0.007" quat="0.178669 0.684162 -0.178669 0.684162" mesh="105mm" material="105mm_material"/>
              <geom type="mesh" class="collision" pos="0.0379454 -0.0212695 -0.007" quat="0.178669 0.684162 -0.178669 0.684162" mesh="105mm" material="105mm_material"/>
              <!-- Frame closing_BL_leg0_2_1_1 -->
              <site group="3" name="closing_BL_leg0_2_1_1" pos="0.0758909 -0.0425391 0.001" quat="0.505492 2.77556e-16 3.33067e-16 -0.862831"/>
              <!-- Frame closing_BL_leg0_2_1_1_z -->
              <site group="3" name="closing_BL_leg0_2_1_1_z" pos="0.0758909 -0.0425391 0.101" quat="0.505492 2.77556e-16 3.33067e-16 -0.862831"/>
            </body>
          </body>
        </body>
      </body>
      <!-- Link part_1_4 -->
      <body name="part_1_4" pos="0.0860451 -0.0418958 -0.0543461" quat="0.707107 -0.707107 -1.53544e-13 -1.53501e-13">
        <!-- Joint from chassisasm to part_1_4 -->
        <joint axis="0 0 1" name="BR_hip" type="hinge"/>
        <inertial pos="-0.00389251 0.000155037 -0.0902192" mass="0.317826" fullinertia="0.00024131 0.000176033 0.000122338 9.78082e-07 -9.71394e-08 -1.04169e-06"/>
        <!-- Part hip_joint_to_bearing_shaft_4 -->
        <geom type="mesh" class="visual" pos="2.77556e-17 -6.93889e-18 -0.233675" quat="0.5 0.5 0.5 -0.5" mesh="hip_joint_to_bearing_shaft__2" material="hip_joint_to_bearing_shaft__2_material"/>
        <geom type="mesh" class="collision" pos="2.77556e-17 -6.93889e-18 -0.233675" quat="0.5 0.5 0.5 -0.5" mesh="hip_joint_to_bearing_shaft__2" material="hip_joint_to_bearing_shaft__2_material"/>
        <!-- Part part_1_24 -->
        <geom type="mesh" class="visual" pos="0 0 -0.0075" quat="0.5 0.5 0.5 -0.5" mesh="part_1__3" material="part_1__3_material"/>
        <geom type="mesh" class="collision" pos="0 0 -0.0075" quat="0.5 0.5 0.5 -0.5" mesh="part_1__3" material="part_1__3_material"/>
        <!-- Part part_1_25 -->
        <geom type="mesh" class="visual" pos="0 0 0" quat="0.707107 0.707107 0 1.15194e-43" mesh="part_1__4" material="part_1__4_material"/>
        <geom type="mesh" class="collision" pos="0 0 0" quat="0.707107 0.707107 0 1.15194e-43" mesh="part_1__4" material="part_1__4_material"/>
        <!-- Part motor_part_hip_joint_4 -->
        <geom type="mesh" class="visual" pos="0.017675 2.08167e-17 -0.079925" quat="0.5 0.5 0.5 -0.5" mesh="motor_part_hip_joint" material="motor_part_hip_joint_material"/>
        <geom type="mesh" class="collision" pos="0.017675 2.08167e-17 -0.079925" quat="0.5 0.5 0.5 -0.5" mesh="motor_part_hip_joint" material="motor_part_hip_joint_material"/>
        <!-- Part x2_8010632f54c130b130fc30b903a6_x0_10x9_5l_side_code_g_2_11 -->
        <geom type="mesh" class="visual" pos="-0.017675 -2.80092e-06 -0.088506" quat="0.5 0.5 -0.5 -0.5" mesh="x2_8010632f54c130b130fc30b903a6_x0_10x9_5l_side_code_g_2__2" material="x2_8010632f54c130b130fc30b903a6_x0_10x9_5l_side_code_g_2__2_material"/>
        <geom type="mesh" class="collision" pos="-0.017675 -2.80092e-06 -0.088506" quat="0.5 0.5 -0.5 -0.5" mesh="x2_8010632f54c130b130fc30b903a6_x0_10x9_5l_side_code_g_2__2" material="x2_8010632f54c130b130fc30b903a6_x0_10x9_5l_side_code_g_2__2_material"/>
        <!-- Part part_1_26 -->
        <geom type="mesh" class="visual" pos="-0.009 2.08167e-17 -0.088675" quat="1.21444e-16 0.707107 -0.707107 -2.11447e-15" mesh="part_1__5" material="part_1__5_material"/>
        <geom type="mesh" class="collision" pos="-0.009 2.08167e-17 -0.088675" quat="1.21444e-16 0.707107 -0.707107 -2.11447e-15" mesh="part_1__5" material="part_1__5_material"/>
        <!-- Part motor_controller_hip_part_4 -->
        <geom type="mesh" class="visual" pos="-0.0145 0 -0.079925" quat="0.5 0.5 0.5 -0.5" mesh="motor_controller_hip_part" material="motor_controller_hip_part_material"/>
        <geom type="mesh" class="collision" pos="-0.0145 0 -0.079925" quat="0.5 0.5 0.5 -0.5" mesh="motor_controller_hip_part" material="motor_controller_hip_part_material"/>
        <!-- Part part_1_27 -->
        <geom type="mesh" class="visual" pos="-0.009 6.93889e-18 -0.173675" quat="1.21444e-16 0.707107 -0.707107 -2.11447e-15" mesh="part_1" material="part_1_material"/>
        <geom type="mesh" class="collision" pos="-0.009 6.93889e-18 -0.173675" quat="1.21444e-16 0.707107 -0.707107 -2.11447e-15" mesh="part_1" material="part_1_material"/>
        <!-- Part spacer_7 -->
        <geom type="mesh" class="visual" pos="0 -1.38778e-17 -0.028675" quat="0.707107 -3.22542e-16 0.707107 -5.55112e-16" mesh="spacer" material="spacer_material"/>
        <geom type="mesh" class="collision" pos="0 -1.38778e-17 -0.028675" quat="0.707107 -3.22542e-16 0.707107 -5.55112e-16" mesh="spacer" material="spacer_material"/>
        <!-- Part x2_8010632f54c130b130fc30b903a6_x0_10x9_5l_side_code_g_2_12 -->
        <geom type="mesh" class="visual" pos="-0.017675 -2.80092e-06 -0.173506" quat="0.5 0.5 -0.5 -0.5" mesh="x2_8010632f54c130b130fc30b903a6_x0_10x9_5l_side_code_g_2" material="x2_8010632f54c130b130fc30b903a6_x0_10x9_5l_side_code_g_2_material"/>
        <geom type="mesh" class="collision" pos="-0.017675 -2.80092e-06 -0.173506" quat="0.5 0.5 -0.5 -0.5" mesh="x2_8010632f54c130b130fc30b903a6_x0_10x9_5l_side_code_g_2" material="x2_8010632f54c130b130fc30b903a6_x0_10x9_5l_side_code_g_2_material"/>
        <!-- Part spacer_8 -->
        <geom type="mesh" class="visual" pos="0 2.08167e-17 -0.214625" quat="0.707107 -1.57009e-16 0.707107 3.33067e-16" mesh="spacer" material="spacer_material"/>
        <geom type="mesh" class="collision" pos="0 2.08167e-17 -0.214625" quat="0.707107 -1.57009e-16 0.707107 3.33067e-16" mesh="spacer" material="spacer_material"/>
        <!-- Link part_1_5 -->
        <body name="part_1_5" pos="0.007 0 -0.173675" quat="9.14302e-14 -0.707107 -9.13714e-14 0.707107">
          <!-- Joint from part_1_4 to part_1_5 -->
          <joint axis="0 0 1" name="BR_a" type="hinge"/>
          <inertial pos="0.0085308 -0.00277183 -0.0196416" mass="0.0670155" fullinertia="2.51735e-05 4.42534e-05 2.88139e-05 6.93117e-06 1.1353e-05 -3.68881e-06"/>
          <!-- Part part_1_28 -->
          <geom type="mesh" class="visual" pos="0 0 0" quat="0.707107 0.707107 -0 8.28714e-30" mesh="part_1__6" material="part_1__6_material"/>
          <geom type="mesh" class="collision" pos="0 0 0" quat="0.707107 0.707107 -0 8.28714e-30" mesh="part_1__6" material="part_1__6_material"/>
          <!-- Part 80mm_4 -->
          <geom type="mesh" class="visual" pos="0.0293289 -0.00952953 -0.0395" quat="0.698401 0.110616 0.698401 -0.110616" mesh="80mm__2" material="80mm__2_material"/>
          <geom type="mesh" class="collision" pos="0.0293289 -0.00952953 -0.0395" quat="0.698401 0.110616 0.698401 -0.110616" mesh="80mm__2" material="80mm__2_material"/>
          <!-- Part shaftcouplerleft_4 -->
          <geom type="mesh" class="visual" pos="0 -6.93889e-18 -0.0075" quat="2.60902e-15 -2.6986e-15 0.707107 0.707107" mesh="shaftcouplerleft__2" material="shaftcouplerleft__2_material"/>
          <geom type="mesh" class="collision" pos="0 -6.93889e-18 -0.0075" quat="2.60902e-15 -2.6986e-15 0.707107 0.707107" mesh="shaftcouplerleft__2" material="shaftcouplerleft__2_material"/>
          <!-- Frame closing_BR_leg0_2 -->
          <site group="3" name="closing_BR_leg0_2" pos="0.0588116 -0.0191091 -0.0315" quat="3.70043e-15 0.156434 0.987688 5.71533e-16"/>
          <!-- Frame closing_BR_leg0_2_z -->
          <site group="3" name="closing_BR_leg0_2_z" pos="0.0588116 -0.0191091 -0.1315" quat="3.70043e-15 0.156434 0.987688 5.71533e-16"/>
        </body>
        <!-- Link part_1_6 -->
        <body name="part_1_6" pos="0.007 1.38778e-17 -0.088675" quat="3.98669e-14 -0.707107 -3.9857e-14 0.707107">
          <!-- Joint from part_1_4 to part_1_6 -->
          <joint axis="0 0 1" name="BR_l" type="hinge"/>
          <inertial pos="-0.0106914 -0.00776778 -0.0228706" mass="0.0307741" fullinertia="6.88639e-06 1.0304e-05 1.33122e-05 -5.25919e-06 -5.36101e-07 -3.89498e-07"/>
          <!-- Part shaftcouplerright_4 -->
          <geom type="mesh" class="visual" pos="0 0 -0.0075" quat="0.5 0.5 -0.5 -0.5" mesh="shaftcouplerright__2" material="shaftcouplerright__2_material"/>
          <geom type="mesh" class="collision" pos="0 0 -0.0075" quat="0.5 0.5 -0.5 -0.5" mesh="shaftcouplerright__2" material="shaftcouplerright__2_material"/>
          <!-- Part part_1_29 -->
          <geom type="mesh" class="visual" pos="0 0 0" quat="0.707107 0.707107 -0 4.5639e-30" mesh="part_1__4" material="part_1__4_material"/>
          <geom type="mesh" class="collision" pos="0 0 0" quat="0.707107 0.707107 -0 4.5639e-30" mesh="part_1__4" material="part_1__4_material"/>
          <!-- Part 68mm_4 -->
          <geom type="mesh" class="visual" pos="-0.0200945 -0.0145995 -0.0245" quat="0.218508 0.672499 0.218508 -0.672499" mesh="68mm__2" material="68mm__2_material"/>
          <geom type="mesh" class="collision" pos="-0.0200945 -0.0145995 -0.0245" quat="0.218508 0.672499 0.218508 -0.672499" mesh="68mm__2" material="68mm__2_material"/>
          <!-- Link 225mmtop_4 -->
          <body name="225mmtop_4" pos="-2.77556e-17 -1.38778e-17 -0.0325" quat="0.902929 0 1.11022e-16 0.42979">
            <!-- Joint from part_1_6 to 225mmtop_4 -->
            <joint axis="0 0 1" name="BR_leg1" type="hinge"/>
            <inertial pos="1.28968e-18 -0.103396 -0.008" mass="0.0562684" fullinertia="0.000237245 2.00635e-06 0.000237309 -3.32196e-21 -4.01116e-33 1.84905e-33"/>
            <!-- Part 225mmtop_4 -->
            <geom type="mesh" class="visual" pos="0 -0.1035 -0.008" quat="0.5 0.5 0.5 -0.5" mesh="225mmtop__2" material="225mmtop__2_material"/>
            <geom type="mesh" class="collision" pos="0 -0.1035 -0.008" quat="0.5 0.5 0.5 -0.5" mesh="225mmtop__2" material="225mmtop__2_material"/>
            <!-- Frame closing_BR_leg3_2 -->
            <site group="3" name="closing_BR_leg3_2" pos="3.46945e-17 -0.207 0" quat="1.16298e-29 0.707107 0.707107 1.80631e-29"/>
            <!-- Frame closing_BR_leg3_2_z -->
            <site group="3" name="closing_BR_leg3_2_z" pos="2.77556e-17 -0.207 -0.1" quat="1.16298e-29 0.707107 0.707107 1.80631e-29"/>
            <!-- Link 105mm_4 -->
            <body name="105mm_4" pos="6.93889e-18 -0.166278 0" quat="0 1 0 0">
              <!-- Joint from 225mmtop_4 to 105mm_4 -->
              <joint axis="0 0 1" name="BR_leg_cyl_0" type="hinge"/>
              <inertial pos="0.0379253 -0.0213054 -0.009" mass="0.0262025" fullinertia="6.59739e-06 1.87892e-05 2.44536e-05 1.00071e-05 -3.45739e-21 1.93358e-21"/>
              <!-- Part 105mm_4 -->
              <geom type="mesh" class="visual" pos="0.0379253 -0.0213054 -0.009" quat="0.178993 0.684077 -0.178993 0.684077" mesh="105mm__2" material="105mm__2_material"/>
              <geom type="mesh" class="collision" pos="0.0379253 -0.0213054 -0.009" quat="0.178993 0.684077 -0.178993 0.684077" mesh="105mm__2" material="105mm__2_material"/>
              <!-- Frame closing_BR_leg0_1 -->
              <site group="3" name="closing_BR_leg0_1" pos="0.0758506 -0.0426108 -0.001" quat="0.505085 1.11022e-16 -0 -0.86307"/>
              <!-- Frame closing_BR_leg0_1_z -->
              <site group="3" name="closing_BR_leg0_1_z" pos="0.0758506 -0.0426108 0.099" quat="0.505085 1.11022e-16 -0 -0.86307"/>
            </body>
          </body>
          <!-- Link 225mmbottom_4 -->
          <body name="225mmbottom_4" pos="-0.0403199 -0.0292942 -0.0325" quat="0.903102 0 -1.53481e-26 0.429425">
            <!-- Joint from part_1_6 to 225mmbottom_4 -->
            <joint axis="0 0 1" name="BR_leg2" type="hinge"/>
            <inertial pos="-8.83579e-18 -0.1035 -0.008" mass="0.0563618" fullinertia="0.000237565 1.94076e-06 0.000237608 1.07509e-21 -1.11628e-32 -7.96742e-33"/>
            <!-- Part 225mmbottom_4 -->
            <geom type="mesh" class="visual" pos="-1.21431e-17 -0.1035 -0.008" quat="0.5 -0.5 -0.5 -0.5" mesh="225mmbottom__2" material="225mmbottom__2_material"/>
            <geom type="mesh" class="collision" pos="-1.21431e-17 -0.1035 -0.008" quat="0.5 -0.5 -0.5 -0.5" mesh="225mmbottom__2" material="225mmbottom__2_material"/>
            <!-- Link 160mm_4 -->
            <body name="160mm_4" pos="8.67362e-18 -0.207 0" quat="0 1 0 0">
              <!-- Joint from 225mmbottom_4 to 160mm_4 -->
              <joint axis="0 0 1" name="BR_leg_cyl_1" type="hinge"/>
              <inertial pos="-0.0205033 -0.00542213 -0.008" mass="0.0400222" fullinertia="6.94585e-06 8.04636e-05 8.60343e-05 -2.09038e-05 -5.4074e-32 2.09855e-31"/>
              <!-- Part 160mm_4 -->
              <geom type="mesh" class="visual" pos="-0.0203021 -0.00536893 -0.008" quat="0.0911511 -0.701207 -0.0911511 -0.701207" mesh="160mm__2" material="160mm__2_material"/>
              <geom type="mesh" class="collision" pos="-0.0203021 -0.00536893 -0.008" quat="0.0911511 -0.701207 -0.0911511 -0.701207" mesh="160mm__2" material="160mm__2_material"/>
              <!-- Frame closing_BR_leg3_1 -->
              <site group="3" name="closing_BR_leg3_1" pos="0.0483383 0.0127832 -5.55112e-17" quat="0.792358 -0 1.03499e-27 -0.610056"/>
              <!-- Frame closing_BR_leg3_1_z -->
              <site group="3" name="closing_BR_leg3_1_z" pos="0.0483383 0.0127832 0.1" quat="0.792358 -0 1.03499e-27 -0.610056"/>
            </body>
          </body>
        </body>
      </body>
    </body>
  </worldbody>
  <asset>
    <mesh file="shaftcouplerright__2.stl"/>
    <mesh file="motor_part_hip_joint.stl"/>
    <mesh file="part_1.stl"/>
    <mesh file="motor_controller_holder.stl"/>
    <mesh file="part_1__4.stl"/>
    <mesh file="x2_8010632f54c130b130fc30b903a6_x0_10x9_5l_side_code_g_2.stl"/>
    <mesh file="68mm__2.stl"/>
    <mesh file="hip_joint_to_bearing_shaft__2.stl"/>
    <mesh file="160mm.stl"/>
    <mesh file="105mm.stl"/>
    <mesh file="bearing_mount__2.stl"/>
    <mesh file="80mm.stl"/>
    <mesh file="part_1__6.stl"/>
    <mesh file="160mm__2.stl"/>
    <mesh file="225mmbottom.stl"/>
    <mesh file="225mmtop.stl"/>
    <mesh file="motor_controller_hip_part.stl"/>
    <mesh file="68mm.stl"/>
    <mesh file="80mm__2.stl"/>
    <mesh file="x2_8010632f54c130b130fc30b903a6_x0_10x9_5l_side_code_g_2__2.stl"/>
    <mesh file="motor_controller_holder__2.stl"/>
    <mesh file="105mm__2.stl"/>
    <mesh file="part_1__2.stl"/>
    <mesh file="part_1__5.stl"/>
    <mesh file="hip_joint_to_bearing_shaft.stl"/>
    <mesh file="bearing_mount.stl"/>
    <mesh file="shaftcouplerright.stl"/>
    <mesh file="motor_holder__2.stl"/>
    <mesh file="225mmtop__2.stl"/>
    <mesh file="225mmbottom__2.stl"/>
    <mesh file="spacer.stl"/>
    <mesh file="part_1__3.stl"/>
    <mesh file="motor_holder.stl"/>
    <mesh file="shaftcouplerleft.stl"/>
    <mesh file="shaftcouplerleft__2.stl"/>
    <material name="part_1_material" rgba="0.647059 0.647059 0.647059 1"/>
    <material name="part_1__2_material" rgba="0.615686 0.811765 0.929412 1"/>
    <material name="motor_controller_holder_material" rgba="0.615686 0.811765 0.929412 1"/>
    <material name="x2_8010632f54c130b130fc30b903a6_x0_10x9_5l_side_code_g_2_material" rgba="0.74902 0.74902 0.74902 1"/>
    <material name="motor_holder_material" rgba="0.647059 0.647059 0.647059 1"/>
    <material name="bearing_mount_material" rgba="0.615686 0.811765 0.929412 1"/>
    <material name="bearing_mount__2_material" rgba="0.615686 0.811765 0.929412 1"/>
    <material name="motor_controller_holder__2_material" rgba="0.615686 0.811765 0.929412 1"/>
    <material name="motor_holder__2_material" rgba="0.647059 0.647059 0.647059 1"/>
    <material name="part_1__3_material" rgba="0.615686 0.811765 0.929412 1"/>
    <material name="part_1__4_material" rgba="0.498039 0.498039 0.498039 1"/>
    <material name="hip_joint_to_bearing_shaft_material" rgba="0.615686 0.811765 0.929412 1"/>
    <material name="motor_part_hip_joint_material" rgba="0.615686 0.811765 0.929412 1"/>
    <material name="x2_8010632f54c130b130fc30b903a6_x0_10x9_5l_side_code_g_2__2_material" rgba="0.74902 0.74902 0.74902 1"/>
    <material name="part_1__5_material" rgba="0.647059 0.647059 0.647059 1"/>
    <material name="motor_controller_hip_part_material" rgba="0.615686 0.811765 0.929412 1"/>
    <material name="spacer_material" rgba="0.615686 0.811765 0.929412 1"/>
    <material name="shaftcouplerright_material" rgba="0.615686 0.811765 0.929412 1"/>
    <material name="68mm_material" rgba="0.615686 0.811765 0.929412 1"/>
    <material name="225mmbottom_material" rgba="0.615686 0.811765 0.929412 1"/>
    <material name="160mm_material" rgba="0.615686 0.811765 0.929412 1"/>
    <material name="225mmtop_material" rgba="0.615686 0.811765 0.929412 1"/>
    <material name="105mm_material" rgba="0.615686 0.811765 0.929412 1"/>
    <material name="80mm_material" rgba="0.615686 0.811765 0.929412 1"/>
    <material name="shaftcouplerleft_material" rgba="0.615686 0.811765 0.929412 1"/>
    <material name="hip_joint_to_bearing_shaft__2_material" rgba="0.615686 0.811765 0.929412 1"/>
    <material name="part_1__6_material" rgba="0.498039 0.498039 0.498039 1"/>
    <material name="80mm__2_material" rgba="0.615686 0.811765 0.929412 1"/>
    <material name="shaftcouplerleft__2_material" rgba="0.615686 0.811765 0.929412 1"/>
    <material name="shaftcouplerright__2_material" rgba="0.615686 0.811765 0.929412 1"/>
    <material name="68mm__2_material" rgba="0.615686 0.811765 0.929412 1"/>
    <material name="225mmtop__2_material" rgba="0.615686 0.811765 0.929412 1"/>
    <material name="105mm__2_material" rgba="0.615686 0.811765 0.929412 1"/>
    <material name="225mmbottom__2_material" rgba="0.615686 0.811765 0.929412 1"/>
    <material name="160mm__2_material" rgba="0.615686 0.811765 0.929412 1"/>
  </asset>
  <actuator>
    <position class="catbot" name="FL_hip" joint="FL_hip"/>
    <position class="catbot" name="FL_l" joint="FL_l"/>
    <position class="catbot" name="FL_leg2_2" joint="FL_leg2_2"/>
    <position class="catbot" name="FL_leg_cyl_1_2" joint="FL_leg_cyl_1_2"/>
    <position class="catbot" name="FL_leg_5_2" joint="FL_leg_5_2"/>
    <position class="catbot" name="FL_leg_cyl_0_2" joint="FL_leg_cyl_0_2"/>
    <position class="catbot" name="FL_a" joint="FL_a"/>
    <position class="catbot" name="FR_hip" joint="FR_hip"/>
    <position class="catbot" name="FR_a" joint="FR_a"/>
    <position class="catbot" name="FR_l" joint="FR_l"/>
    <position class="catbot" name="FR_leg1_1" joint="FR_leg1_1"/>
    <position class="catbot" name="FR_leg_cyl_0_1" joint="FR_leg_cyl_0_1"/>
    <position class="catbot" name="FR_leg2_1" joint="FR_leg2_1"/>
    <position class="catbot" name="FR_leg_cyl_1_1" joint="FR_leg_cyl_1_1"/>
    <position class="catbot" name="BL_hip" joint="BL_hip"/>
    <position class="catbot" name="BL_a" joint="BL_a"/>
    <position class="catbot" name="BL_l" joint="BL_l"/>
    <position class="catbot" name="BL_leg2_2_1" joint="BL_leg2_2_1"/>
    <position class="catbot" name="BL_leg_cyl_1_2_1" joint="BL_leg_cyl_1_2_1"/>
    <position class="catbot" name="BL_leg_5_2_1" joint="BL_leg_5_2_1"/>
    <position class="catbot" name="BL_leg_cyl_0_2_1" joint="BL_leg_cyl_0_2_1"/>
    <position class="catbot" name="BR_hip" joint="BR_hip"/>
    <position class="catbot" name="BR_a" joint="BR_a"/>
    <position class="catbot" name="BR_l" joint="BR_l"/>
    <position class="catbot" name="BR_leg1" joint="BR_leg1"/>
    <position class="catbot" name="BR_leg_cyl_0" joint="BR_leg_cyl_0"/>
    <position class="catbot" name="BR_leg2" joint="BR_leg2"/>
    <position class="catbot" name="BR_leg_cyl_1" joint="BR_leg_cyl_1"/>
  </actuator>
  <equality>
    <connect site1="closing_BR_leg0_1" site2="closing_BR_leg0_2"/>
    <connect site1="closing_BR_leg0_1_z" site2="closing_BR_leg0_2_z"/>
    <connect site1="closing_BR_leg3_1" site2="closing_BR_leg3_2"/>
    <connect site1="closing_BR_leg3_1_z" site2="closing_BR_leg3_2_z"/>
    <connect site1="closing_FR_leg0_1_1" site2="closing_FR_leg0_1_2"/>
    <connect site1="closing_FR_leg0_1_1_z" site2="closing_FR_leg0_1_2_z"/>
    <connect site1="closing_FR_leg3_1_1" site2="closing_FR_leg3_1_2"/>
    <connect site1="closing_FR_leg3_1_1_z" site2="closing_FR_leg3_1_2_z"/>
    <connect site1="closing_FL_leg0_2_1" site2="closing_FL_leg0_2_2"/>
    <connect site1="closing_FL_leg0_2_1_z" site2="closing_FL_leg0_2_2_z"/>
    <connect site1="closing_FL_leg3_2_1" site2="closing_FL_leg3_2_2"/>
    <connect site1="closing_FL_leg3_2_1_z" site2="closing_FL_leg3_2_2_z"/>
    <connect site1="closing_BL_leg0_2_1_1" site2="closing_BL_leg0_2_1_2"/>
    <connect site1="closing_BL_leg0_2_1_1_z" site2="closing_BL_leg0_2_1_2_z"/>
    <connect site1="closing_BL_leg3_2_1_1" site2="closing_BL_leg3_2_1_2"/>
    <connect site1="closing_BL_leg3_2_1_1_z" site2="closing_BL_leg3_2_1_2_z"/>
  </equality>
</mujoco>
